Workbook
Name Slicer_Price: #N/A
Name Slicer_Rainfall: #N/A

Sheet data
A1: Date | B1: Month | C1: Day | D1: Temperature | E1: Rainfall | F1: RainfallCategory | G1: Flyers | H1: FlyerSuccess | I1: FlyerSuccessScore | J1: Price | K1: Sales | L1: Target | M1: OverallPerformance | N1: Revenue
A2: 42736 | B2: Jan | C2: Sunday | D2: 27 | E2: 2 | F2: Heavy | G2: 15 | H2: Low | I2: 5 | J2: 0.3 | K2: 10 | L2: 8 | M2: 5 | N2: 3
A3: 42737 | B3: Jan | C3: Monday | D3: 28.9 | E3: 1.33 | F3: Heavy | G3: 15 | H3: Low | I3: 5 | J3: 0.3 | K3: 13 | L3: 8 | M3: 5 | N3: 3.9
A4: 42738 | B4: Jan | C4: Tuesday | D4: 34.5 | E4: 1.33 | F4: Heavy | G4: 27 | H4: Medium | I4: 10 | J4: 0.3 | K4: 15 | L4: 8 | M4: 10 | N4: 4.5
A5: 42739 | B5: Jan | C5: Wednesday | D5: 44.1 | E5: 1.05 | F5: Heavy | G5: 28 | H5: Medium | I5: 10 | J5: 0.3 | K5: 17 | L5: 8 | M5: 10 | N5: 5.1
A6: 42740 | B6: Jan | C6: Thursday | D6: 42.4 | E6: 1 | F6: Medium | G6: 33 | H6: Medium | I6: 10 | J6: 0.3 | K6: 18 | L6: 8 | M6: 10 | N6: 5.4
A7: 42741 | B7: Jan | C7: Friday | D7: 25.3 | E7: 1.54 | F7: Heavy | G7: 23 | H7: Medium | I7: 10 | J7: 0.3 | K7: 11 | L7: 8 | M7: 10 | N7: 3.3
A8: 42742 | B8: Jan | C8: Saturday | D8: 32.9 | E8: 0 | F8: None | G8: 19 | H8: Low | I8: 5 | J8: 0.3 | K8: 13 | L8: 8 | M8: 5 | N8: 3.9
A9: 42743 | B9: Jan | C9: Sunday | D9: 37.5 | E9: 1.18 | F9: Heavy | G9: 28 | H9: Medium | I9: 10 | J9: 0.3 | K9: 15 | L9: 8 | M9: 10 | N9: 4.5
A10: 42744 | B10: Jan | C10: Monday | D10: 38.1 | E10: 1.18 | F10: Heavy | G10: 20 | H10: Medium | I10: 10 | J10: 0.3 | K10: 17 | L10: 8 | M10: 10 | N10: 5.1
A11: 42745 | B11: Jan | C11: Tuesday | D11: 43.4 | E11: 1.05 | F11: Heavy | G11: 33 | H11: Medium | I11: 10 | J11: 0.3 | K11: 18 | L11: 8 | M11: 10 | N11: 5.4
A12: 42746 | B12: Jan | C12: Wednesday | D12: 32.6 | E12: 1.54 | F12: Heavy | G12: 23 | H12: Medium | I12: 10 | J12: 0.3 | K12: 12 | L12: 8 | M12: 10 | N12: 3.6
A13: 42747 | B13: Jan | C13: Thursday | D13: 38.2 | E13: 0 | F13: None | G13: 16 | H13: Low | I13: 5 | J13: 0.3 | K13: 14 | L13: 8 | M13: 5 | N13: 4.2
... A388: 43040 | B388: Nov | C388: Wednesday | D388: 51.9 | E388: 0 | F388: None | G388: 43 | H388: High | I388: 15 | J388: 0.3 | K388: 23 | L388: 8 | M388: 15 | N388: 6.9

Sheet Q1
V3: Total Points Received | X3: =SUM(X16,'Q2'!Q8,'Q3'!P8,'Q4'!N17) -> 0 | Y3: =SUM(W16,'Q2'!P8,'Q3'!O8,'Q4'!M17) -> 30
V4: To pass | W4: 17 Points
V5: Q1 | W5: Points
V6: Task1 | W6: 1
V7: Task2 | W7: 1
V8: Task3 | W8: 1
V9: Task4 | W9: 1
V10: Task5 | W10: 1
V11: Task6 | W11: 1
V12: Task7 | W12: 1
V13: Task8 | W13: 1
V14: Task9 | W14: 1
V15: Task10 | W15: 1
V16: Total | W16: =SUM(W6:W15) -> 10 | X16: =SUM(X6:X15) -> 0

Sheet Q2
A1: Game Stats
A2: Day Played | B2: Game 1 | C2: Game 2 | D2: Game 3 | E2: Average Wins | F2: Number of plays | G2: =COUNT(B3:D12) -> 30
A3: Day 1 | B3: 1 | C3: 1 | D3: 0 | E3: =AVERAGEA(B3:D3) -> 0.66666667 | F3: Total wins | G3: =COUNTIF(B3:D12,1) -> 16 | P3: Points
A4: Day 2 | B4: 1 | C4: 0 | D4: 0 | E4: =AVERAGEA(B4:D4) -> 0.33333333 | F4: Total losses | G4: =G2-G3 -> 14 | O4: Task1 | P4: 1
A5: Day 3 | B5: 0 | C5: 0 | D5: 0 | E5: =AVERAGEA(B5:D5) -> 0 | O5: Task2 | P5: 1
A6: Day 4 | B6: 1 | C6: 0 | D6: 1 | E6: =AVERAGEA(B6:D6) -> 0.66666667 | O6: Task3 | P6: 1
A7: Day 5 | B7: 1 | C7: 0 | D7: 1 | E7: =AVERAGEA(B7:D7) -> 0.66666667 | O7: Task4 | P7: 1
A8: Day 6 | B8: 1 | C8: 0 | D8: 1 | E8: =AVERAGEA(B8:D8) -> 0.66666667 | O8: Total | P8: =SUM(P4:P7) -> 4 | Q8: =SUM(Q4:Q7) -> 0
A9: Day 7 | B9: 1 | C9: 1 | D9: 1 | E9: =AVERAGEA(B9:D9) -> 1
A10: Day 8 | B10: 0 | C10: 1 | D10: 0 | E10: =AVERAGEA(B10:D10) -> 0.33333333
A11: Day 9 | B11: 1 | C11: 1 | D11: 0 | E11: =AVERAGEA(B11:D11) -> 0.66666667
A12: Day 10 | B12: 0 | C12: 1 | D12: 0 | E12: =AVERAGEA(B12:D12) -> 0.33333333

Sheet Q3
O1: Points
N2: Task1 | O2: 2
A3: Activity | B3: Start Time | C3: Duration | N3: Task2 | O3: 2
A4: A | B4: 0 | C4: 4 | N4: Task3 | O4: 2
A5: B | B5: 3 | C5: 6 | E5: Please see Charts Sheet | N5: Task4 | O5: 1
A6: C | B6: 5 | C6: 7 | N6: Task5 | O6: 2
A7: D | B7: 6 | C7: 8 | N7: Task6 | O7: 2
A8: E | B8: 3 | C8: 7 | N8: Total | O8: =SUM(O2:O7) -> 11 | P8: =SUM(P2:P7) -> 0
A13: Item | B13: Amount
A14: Revenue | B14: 300000 | D14: Please see Charts Sheet
A15: Profit | B15: 65000
A16: Labor Costs | B16: 100000
A17: Material Costs | B17: 80000
A18: Overhead Costs | B18: 55000
A22: Email | B22: First name | C22: Last name
A23: Nancy.Smith@contoso.com | B23: Nancy | C23: Smith | D23: Ans = Used Fill Flash
A24: Andy.North@fabrikam.com | B24: Andy | C24: North | E24: Shortcut :Ctrl + E
A25: Jan.Kotas@relecloud.com | B25: Jan | C25: Kotas
A26: Mariya.Jones@contoso.com | B26: Mariya | C26: Jones
A27: Yvonne.McKay@fabrikam.com | B27: Yvonne | C27: McKay
A30: Fruit | B30: Amount | D30: Meat | E30: Amount
A31: Apples | B31: 50 | D31: Beef | E31: 50
A32: Oranges | B32: 20 | D32: Chicken | E32: 30
A33: Bananas | B33: 60 | D33: Pork | E33: 10
A34: Lemons | B34: 40 | D34: Fish | E34: 50
A35: MIN > | B35: =MIN(B31:B34) -> 20 | D35: MAX > | E35: =MAX(E31:E34) -> 50
A38: First Name | B38: Last Name | C38: Full Name
A39: Nancy | B39: Smith | C39: =A39&" "&B39 -> Nancy Smith
A40: Andy | B40: North | C40: =A40&" "&B40 -> Andy North
A41: Jan | B41: Kotas | C41: =A41&" "&B41 -> Jan Kotas
A42: Mariya | B42: Jones | C42: =A42&" "&B42 -> Mariya Jones
A43: Steven | B43: Thorpe | C43: =A43&" "&B43 -> Steven Thorpe
A44: Michael | B44: Neipper | C44: =A44&" "&B44 -> Michael Neipper
A45: Robert | B45: Zare | C45: =A45&" "&B45 -> Robert Zare
A46: Yvonne | B46: McKay | C46: =A46&" "&B46 -> Yvonne McKay
A51: First Name | B51: Last Name | C51: Total Points | D51: Grade | F51: Grading Scale | G51: Grade
A52: Nancy | B52: Smith | C52: 35 | D52: =IF(C52>=80,"5",IF(C52>=70,"4",IF(C52>=60,"3",IF(C52>=50,"2",IF(C52>=40,"1","0"))))) -> 0 | F52: 0 | G52: 0
A53: Andy | B53: North | C53: 69 | D53: =IF(C53>=80,"5",IF(C53>=70,"4",IF(C53>=60,"3",IF(C53>=50,"2",IF(C53>=40,"1","0"))))) -> 3 | F53: 40 | G53: 1
A54: Jan | B54: Kotas | C54: 55 | D54: =IF(C54>=80,"5",IF(C54>=70,"4",IF(C54>=60,"3",IF(C54>=50,"2",IF(C54>=40,"1","0"))))) -> 2 | F54: 50 | G54: 2
A55: Mariya | B55: Jones | C55: 70 | D55: =IF(C55>=80,"5",IF(C55>=70,"4",IF(C55>=60,"3",IF(C55>=50,"2",IF(C55>=40,"1","0"))))) -> 4 | F55: 60 | G55: 3
...

Sheet Charts

Sheet Q4
A1: Data 1 | B1: Column1 | C1: Column2 | D1: Column3 | E1: Column4 | F1: Column5 | H1: Data 2
A2: id | B2: Date | C2: Time In | D2: Time Out | E2: Hours worked | F2: Salary= hours worked *15 | H2: Column1 | I2: Column2 | J2: Column3
A3: HAMK123 | B3: 44044 | C3: 0.33333333 | D3: 0.45833333 | E3: ='Q4'!$D3-'Q4'!$C3 -> 0.125 | F3: =E3*24*15 -> 45 | H3: id | I3: Total Hours | J3: Total Salary
A4: HAMK124 | B4: 44044 | C4: 0.5 | D4: 0.54166667 | E4: ='Q4'!$D4-'Q4'!$C4 -> 0.041666667 | F4: =E4*24*15 -> 15 | H4: HAMK123 | I4: =SUMIF(A$3:A$59,H4,E$3:E$59) -> 0.45833333 | J4: =SUMIF(A$3:A$59,H4,F$3:F459) -> 165
A5: HAMK125 | B5: 44044 | C5: 0.45833333 | D5: 0.66666667 | E5: ='Q4'!$D5-'Q4'!$C5 -> 0.20833333 | F5: =E5*24*15 -> 75 | H5: HAMK124 | I5: =SUMIF(A$3:A$59,H5,E$3:E$59) -> 0.41666667 | J5: =SUMIF(A$3:A$59,H5,F$3:F460) -> 150
A6: HAMK126 | B6: 44044 | C6: 0.41666667 | D6: 0.75 | E6: ='Q4'!$D6-'Q4'!$C6 -> 0.33333333 | F6: =E6*24*15 -> 120 | H6: HAMK125 | I6: =SUMIF(A$3:A$59,H6,E$3:E$59) -> 0.66666667 | J6: =SUMIF(A$3:A$59,H6,F$3:F461) -> 240
A7: HAMK127 | B7: 44044 | C7: 0.25 | D7: 0.5 | E7: ='Q4'!$D7-'Q4'!$C7 -> 0.25 | F7: =E7*24*15 -> 90 | H7: HAMK126 | I7: =SUMIF(A$3:A$59,H7,E$3:E$59) -> 0.95833333 | J7: =SUMIF(A$3:A$59,H7,F$3:F462) -> 345
A8: HAMK128 | B8: 44044 | C8: 0.29166667 | D8: 0.58333333 | E8: ='Q4'!$D8-'Q4'!$C8 -> 0.29166667 | F8: =E8*24*15 -> 105 | H8: HAMK127 | I8: =SUMIF(A$3:A$59,H8,E$3:E$59) -> 0.875 | J8: =SUMIF(A$3:A$59,H8,F$3:F463) -> 315
A9: HAMK129 | B9: 44044 | C9: 0.375 | D9: 0.75 | E9: ='Q4'!$D9-'Q4'!$C9 -> 0.375 | F9: =E9*24*15 -> 135 | H9: HAMK128 | I9: =SUMIF(A$3:A$59,H9,E$3:E$59) -> 0.79166667 | J9: =SUMIF(A$3:A$59,H9,F$3:F464) -> 285
A10: HAMK130 | B10: 44044 | C10: 0.41666667 | D10: 0.625 | E10: ='Q4'!$D10-'Q4'!$C10 -> 0.20833333 | F10: =E10*24*15 -> 75 | H10: HAMK129 | I10: =SUMIF(A$3:A$59,H10,E$3:E$59) -> 1.25 | J10: =SUMIF(A$3:A$59,H10,F$3:F465) -> 450
A11: HAMK131 | B11: 44044 | C11: 0.25 | D11: 0.75 | E11: ='Q4'!$D11-'Q4'!$C11 -> 0.5 | F11: =E11*24*15 -> 180 | H11: HAMK130 | I11: =SUMIF(A$3:A$59,H11,E$3:E$59) -> 0.70833333 | J11: =SUMIF(A$3:A$59,H11,F$3:F466) -> 255
A12: HAMK132 | B12: 44044 | C12: 0.29166667 | D12: 0.58333333 | E12: ='Q4'!$D12-'Q4'!$C12 -> 0.29166667 | F12: =E12*24*15 -> 105 | H12: HAMK131 | I12: =SUMIF(A$3:A$59,H12,E$3:E$59) -> 1.125 | J12: =SUMIF(A$3:A$59,H12,F$3:F467) -> 405
A13: HAMK133 | B13: 44044 | C13: 0.375 | D13: 0.5 | E13: ='Q4'!$D13-'Q4'!$C13 -> 0.125 | F13: =E13*24*15 -> 45 | H13: HAMK132 | I13: =SUMIF(A$3:A$59,H13,E$3:E$59) -> 0.83333333 | J13: =SUMIF(A$3:A$59,H13,F$3:F468) -> 300 | M13: Points
A14: HAMK134 | B14: 44044 | C14: 0.25 | D14: 0.5 | E14: ='Q4'!$D14-'Q4'!$C14 -> 0.25 | F14: =E14*24*15 -> 90 | H14: HAMK133 | I14: =SUMIF(A$3:A$59,H14,E$3:E$59) -> 0.58333333 | J14: =SUMIF(A$3:A$59,H14,F$3:F469) -> 210 | L14: Task1 | M14: 1
A15: HAMK135 | B15: 44044 | C15: 0.29166667 | D15: 0.625 | E15: ='Q4'!$D15-'Q4'!$C15 -> 0.33333333 | F15: =E15*24*15 -> 120 | H15: HAMK134 | I15: =SUMIF(A$3:A$59,H15,E$3:E$59) -> 0.875 | J15: =SUMIF(A$3:A$59,H15,F$3:F470) -> 315 | L15: Task2 | M15: 2
A16: HAMK136 | B16: 44044 | C16: 0.375 | D16: 0.75 | E16: ='Q4'!$D16-'Q4'!$C16 -> 0.375 | F16: =E16*24*15 -> 135 | H16: HAMK135 | I16: =SUMIF(A$3:A$59,H16,E$3:E$59) -> 0.91666667 | J16: =SUMIF(A$3:A$59,H16,F$3:F471) -> 330 | L16: Task3 | M16: 2
A17: HAMK137 | B17: 44044 | C17: 0.25 | D17: 0.5 | E17: ='Q4'!$D17-'Q4'!$C17 -> 0.25 | F17: =E17*24*15 -> 90 | H17: HAMK136 | I17: =SUMIF(A$3:A$59,H17,E$3:E$59) -> 1.0833333 | J17: =SUMIF(A$3:A$59,H17,F$3:F472) -> 390 | L17: Total | M17: =SUM(M14:M16) -> 5 | N17: =SUM(N14:N16) -> 0
A18: HAMK138 | B18: 44044 | C18: 0.29166667 | D18: 0.625 | E18: ='Q4'!$D18-'Q4'!$C18 -> 0.33333333 | F18: =E18*24*15 -> 120 | H18: HAMK137 | I18: =SUMIF(A$3:A$59,H18,E$3:E$59) -> 0.70833333 | J18: =SUMIF(A$3:A$59,H18,F$3:F473) -> 255
A19: HAMK139 | B19: 44044 | C19: 0.375 | D19: 0.58333333 | E19: ='Q4'!$D19-'Q4'!$C19 -> 0.20833333 | F19: =E19*24*15 -> 75 | H19: HAMK138 | I19: =SUMIF(A$3:A$59,H19,E$3:E$59) -> 1.0833333 | J19: =SUMIF(A$3:A$59,H19,F$3:F474) -> 390
A20: HAMK140 | B20: 44044 | C20: 0.25 | D20: 0.66666667 | E20: ='Q4'!$D20-'Q4'!$C20 -> 0.41666667 | F20: =E20*24*15 -> 150 | H20: HAMK139 | I20: =SUMIF(A$3:A$59,H20,E$3:E$59) -> 0.625 | J20: =SUMIF(A$3:A$59,H20,F$3:F475) -> 225
A21: HAMK141 | B21: 44044 | C21: 0.29166667 | D21: 0.5 | E21: ='Q4'!$D21-'Q4'!$C21 -> 0.20833333 | F21: =E21*24*15 -> 75 | H21: HAMK140 | I21: =SUMIF(A$3:A$59,H21,E$3:E$59) -> 1.0416667 | J21: =SUMIF(A$3:A$59,H21,F$3:F476) -> 375
A22: HAMK123 | B22: 44044 | C22: 0.33333333 | D22: 0.45833333 | E22: ='Q4'!$D22-'Q4'!$C22 -> 0.125 | F22: =E22*24*15 -> 45 | H22: HAMK141 | I22: =SUMIF(A$3:A$59,H22,E$3:E$59) -> 0.83333333 | J22: =SUMIF(A$3:A$59,H22,F$3:F477) -> 300
A23: HAMK124 | B23: 44044 | C23: 0.5 | D23: 0.54166667 | E23: ='Q4'!$D23-'Q4'!$C23 -> 0.041666667 | F23: =E23*24*15 -> 15
A24: HAMK125 | B24: 44044 | C24: 0.45833333 | D24: 0.66666667 | E24: ='Q4'!$D24-'Q4'!$C24 -> 0.20833333 | F24: =E24*24*15 -> 75
A25: HAMK126 | B25: 44044 | C25: 0.41666667 | D25: 0.75 | E25: ='Q4'!$D25-'Q4'!$C25 -> 0.33333333 | F25: =E25*24*15 -> 120
A26: HAMK127 | B26: 44044 | C26: 0.25 | D26: 0.5 | E26: ='Q4'!$D26-'Q4'!$C26 -> 0.25 | F26: =E26*24*15 -> 90
A27: HAMK128 | B27: 44044 | C27: 0.29166667 | D27: 0.58333333 | E27: ='Q4'!$D27-'Q4'!$C27 -> 0.29166667 | F27: =E27*24*15 -> 105
A28: HAMK129 | B28: 44044 | C28: 0.375 | D28: 0.75 | E28: ='Q4'!$D28-'Q4'!$C28 -> 0.375 | F28: =E28*24*15 -> 135
A29: HAMK130 | B29: 44044 | C29: 0.41666667 | D29: 0.625 | E29: ='Q4'!$D29-'Q4'!$C29 -> 0.20833333 | F29: =E29*24*15 -> 75
A30: HAMK131 | B30: 44044 | C30: 0.25 | D30: 0.75 | E30: ='Q4'!$D30-'Q4'!$C30 -> 0.5 | F30: =E30*24*15 -> 180
A31: HAMK132 | B31: 44044 | C31: 0.29166667 | D31: 0.58333333 | E31: ='Q4'!$D31-'Q4'!$C31 -> 0.29166667 | F31: =E31*24*15 -> 105
A32: HAMK133 | B32: 44044 | C32: 0.375 | D32: 0.5 | E32: ='Q4'!$D32-'Q4'!$C32 -> 0.125 | F32: =E32*24*15 -> 45
A33: HAMK134 | B33: 44044 | C33: 0.25 | D33: 0.5 | E33: ='Q4'!$D33-'Q4'!$C33 -> 0.25 | F33: =E33*24*15 -> 90
A34: HAMK135 | B34: 44044 | C34: 0.29166667 | D34: 0.625 | E34: ='Q4'!$D34-'Q4'!$C34 -> 0.33333333 | F34: =E34*24*15 -> 120
... A59: HAMK141 | B59: 44045 | C59: 0.25 | D59: 0.66666667 | E59: ='Q4'!$D59-'Q4'!$C59 -> 0.41666667 | F59: =E59*24*15 -> 150

Sheet Sheet1
A1: Date | B1: Month | C1: Day | D1: Temperature | E1: Rainfall | F1: RainfallCategory | G1: Flyers | H1: FlyerSuccess | I1: FlyerSuccessScore | J1: Price | K1: Sales | L1: Target | M1: OverallPerformance | N1: Revenue
A2: 42736 | B2: Jan | C2: Sunday | D2: 27 | E2: 2 | F2: Heavy | G2: 15 | H2: Low | I2: 5 | J2: 0.3 | K2: 10 | L2: 8 | M2: 5 | N2: 3
A3: 42737 | B3: Jan | C3: Monday | D3: 28.9 | E3: 1.33 | F3: Heavy | G3: 15 | H3: Low | I3: 5 | J3: 0.3 | K3: 13 | L3: 8 | M3: 5 | N3: 3.9
A4: 42738 | B4: Jan | C4: Tuesday | D4: 34.5 | E4: 1.33 | F4: Heavy | G4: 27 | H4: Medium | I4: 10 | J4: 0.3 | K4: 15 | L4: 8 | M4: 10 | N4: 4.5
A5: 42739 | B5: Jan | C5: Wednesday | D5: 44.1 | E5: 1.05 | F5: Heavy | G5: 28 | H5: Medium | I5: 10 | J5: 0.3 | K5: 17 | L5: 8 | M5: 10 | N5: 5.1
A6: 42740 | B6: Jan | C6: Thursday | D6: 42.4 | E6: 1 | F6: Medium | G6: 33 | H6: Medium | I6: 10 | J6: 0.3 | K6: 18 | L6: 8 | M6: 10 | N6: 5.4
A7: 42741 | B7: Jan | C7: Friday | D7: 25.3 | E7: 1.54 | F7: Heavy | G7: 23 | H7: Medium | I7: 10 | J7: 0.3 | K7: 11 | L7: 8 | M7: 10 | N7: 3.3
A8: 42742 | B8: Jan | C8: Saturday | D8: 32.9 | E8: 0 | F8: None | G8: 19 | H8: Low | I8: 5 | J8: 0.3 | K8: 13 | L8: 8 | M8: 5 | N8: 3.9
A9: 42743 | B9: Jan | C9: Sunday | D9: 37.5 | E9: 1.18 | F9: Heavy | G9: 28 | H9: Medium | I9: 10 | J9: 0.3 | K9: 15 | L9: 8 | M9: 10 | N9: 4.5
A10: 42744 | B10: Jan | C10: Monday | D10: 38.1 | E10: 1.18 | F10: Heavy | G10: 20 | H10: Medium | I10: 10 | J10: 0.3 | K10: 17 | L10: 8 | M10: 10 | N10: 5.1
A11: 42745 | B11: Jan | C11: Tuesday | D11: 43.4 | E11: 1.05 | F11: Heavy | G11: 33 | H11: Medium | I11: 10 | J11: 0.3 | K11: 18 | L11: 8 | M11: 10 | N11: 5.4
A12: 42746 | B12: Jan | C12: Wednesday | D12: 32.6 | E12: 1.54 | F12: Heavy | G12: 23 | H12: Medium | I12: 10 | J12: 0.3 | K12: 12 | L12: 8 | M12: 10 | N12: 3.6
A13: 42747 | B13: Jan | C13: Thursday | D13: 38.2 | E13: 0 | F13: None | G13: 16 | H13: Low | I13: 5 | J13: 0.3 | K13: 14 | L13: 8 | M13: 5 | N13: 4.2
... A32: 42766 | B32: Jan | C32: Tuesday | D32: 40.4 | E32: 1.05 | F32: Heavy | G32: 37 | H32: Medium | I32: 10 | J32: 0.3 | K32: 18 | L32: 8 | M32: 10 | N32: 5.4

Sheet Q1_Answers
B3: Task 3
K4: Task 4
K7: Row Labels | L7: Revenue per Month | M7: Target per Month
K8: Jan | L8: 138.6 | M8: 248
K9: Feb | L9: 167.1 | M9: 224
K10: Mar | L10: 222.6 | M10: 248
K11: Apr | L11: 235.8 | M11: 240
K12: May | L12: 274.5 | M12: 248
K13: Jun | L13: 316.8 | M13: 240
K14: Jul | L14: 556.5 | M14: 248
K15: Aug | L15: 470.5 | M15: 248
K16: Sep | L16: 357 | M16: 352
K17: Oct | L17: 281.1 | M17: 304
K18: Nov | L18: 196.5 | M18: 248
K19: Dec | L19: 138.6 | M19: 248
K20: Grand Total | L20: 3355.6 | M20: 3096
B23: Task 5 & 6 | G23: Task 7
B25: Row Labels | C25: Revenue per Month | D25: Sum of Target | E25: Performance
B26: Jan | C26: 138.6 | D26: 248 | E26: 265
B27: Feb | C27: 167.1 | D27: 224 | E27: 295
B28: Mar | C28: 222.6 | D28: 248 | E28: 360
B29: Apr | C29: 235.8 | D29: 240 | E29: 520
B30: May | C30: 274.5 | D30: 248 | E30: 730
B31: Jun | C31: 316.8 | D31: 240 | E31: 735
B32: Jul | C32: 556.5 | D32: 248 | E32: 755
B33: Aug | C33: 470.5 | D33: 248 | E33: 750
B34: Sep | C34: 357 | D34: 352 | E34: 830
B35: Oct | C35: 281.1 | D35: 304 | E35: 465
B36: Nov | C36: 196.5 | D36: 248 | E36: 350
B37: Dec | C37: 138.6 | D37: 248 | E37: 260
B38: Grand Total | C38: 3355.6 | D38: 3096 | E38: 6315
B40: Task 8 | E40: Task 9
B41: Month | C41: Max of Revenue | E41: Month | F41: Min of Revenue
B42: Jul | C42: 21.5 | E42: Dec | F42: 2.1
B43: Sunday | C43: 19 | E43: Sunday | F43: 2.1
B44: Monday | C44: 20 | E44: Monday | F44: 3.9
B45: Tuesday | C45: 20.5 | E45: Tuesday | F45: 3
B46: Wednesday | C46: 18 | E46: Wednesday | F46: 4.2
B47: Thursday | C47: 21.5 | E47: Thursday | F47: 3.9
B48: Friday | C48: 20 | E48: Friday | F48: 3.9
...
